[2024-09-02T01:36:58.433+0000] {taskinstance.py:1957} INFO - Dependencies all met for dep_context=non-requeueable deps ti=<TaskInstance: clickhouse_to_sqlite.data_from_clickhouse manual__2024-09-02T01:36:55.231520+00:00 [queued]>
[2024-09-02T01:36:58.436+0000] {taskinstance.py:1957} INFO - Dependencies all met for dep_context=requeueable deps ti=<TaskInstance: clickhouse_to_sqlite.data_from_clickhouse manual__2024-09-02T01:36:55.231520+00:00 [queued]>
[2024-09-02T01:36:58.436+0000] {taskinstance.py:2171} INFO - Starting attempt 1 of 1
[2024-09-02T01:36:58.442+0000] {taskinstance.py:2192} INFO - Executing <Task(_PythonDecoratedOperator): data_from_clickhouse> on 2024-09-02 01:36:55.231520+00:00
[2024-09-02T01:36:58.448+0000] {standard_task_runner.py:60} INFO - Started process 1048 to run task
[2024-09-02T01:36:58.460+0000] {standard_task_runner.py:87} INFO - Running: ['airflow', 'tasks', 'run', 'clickhouse_to_sqlite', 'data_from_clickhouse', 'manual__2024-09-02T01:36:55.231520+00:00', '--job-id', '39', '--raw', '--subdir', 'DAGS_FOLDER/clickhouse_to_sqlite.py', '--cfg-path', '/tmp/tmpiv4z04jo']
[2024-09-02T01:36:58.463+0000] {standard_task_runner.py:88} INFO - Job 39: Subtask data_from_clickhouse
[2024-09-02T01:36:58.484+0000] {task_command.py:423} INFO - Running <TaskInstance: clickhouse_to_sqlite.data_from_clickhouse manual__2024-09-02T01:36:55.231520+00:00 [running]> on host 49db2d0c7729
[2024-09-02T01:36:58.510+0000] {taskinstance.py:2481} INFO - Exporting env vars: AIRFLOW_CTX_DAG_OWNER='airflow' AIRFLOW_CTX_DAG_ID='clickhouse_to_sqlite' AIRFLOW_CTX_TASK_ID='data_from_clickhouse' AIRFLOW_CTX_EXECUTION_DATE='2024-09-02T01:36:55.231520+00:00' AIRFLOW_CTX_TRY_NUMBER='1' AIRFLOW_CTX_DAG_RUN_ID='manual__2024-09-02T01:36:55.231520+00:00'
[2024-09-02T01:37:00.633+0000] {taskinstance.py:2699} ERROR - Task failed with exception
Traceback (most recent call last):
  File "/home/airflow/.local/lib/python3.8/site-packages/airflow/models/taskinstance.py", line 433, in _execute_task
    result = execute_callable(context=context, **execute_callable_kwargs)
  File "/home/airflow/.local/lib/python3.8/site-packages/airflow/decorators/base.py", line 242, in execute
    return_value = super().execute(context)
  File "/home/airflow/.local/lib/python3.8/site-packages/airflow/operators/python.py", line 199, in execute
    return_value = self.execute_callable()
  File "/home/airflow/.local/lib/python3.8/site-packages/airflow/operators/python.py", line 216, in execute_callable
    return self.python_callable(*self.op_args, **self.op_kwargs)
  File "/opt/airflow/dags/clickhouse_to_sqlite.py", line 30, in data_from_clickhouse
    with open(DATA_PATH.joinpath('Question_1.sql'), 'r') as sql_file:
FileNotFoundError: [Errno 2] No such file or directory: '/opt/airflow/data/Question_1.sql'
[2024-09-02T01:37:00.653+0000] {taskinstance.py:1138} INFO - Marking task as FAILED. dag_id=clickhouse_to_sqlite, task_id=data_from_clickhouse, execution_date=20240902T013655, start_date=20240902T013658, end_date=20240902T013700
[2024-09-02T01:37:00.668+0000] {standard_task_runner.py:107} ERROR - Failed to execute job 39 for task data_from_clickhouse ([Errno 2] No such file or directory: '/opt/airflow/data/Question_1.sql'; 1048)
[2024-09-02T01:37:00.686+0000] {local_task_job_runner.py:234} INFO - Task exited with return code 1
[2024-09-02T01:37:00.703+0000] {taskinstance.py:3281} INFO - 0 downstream tasks scheduled from follow-on schedule check
