[2024-09-02T01:17:32.691+0000] {taskinstance.py:1957} INFO - Dependencies all met for dep_context=non-requeueable deps ti=<TaskInstance: clickhouse_to_sqlite.data_from_clickhouse manual__2024-09-02T01:17:30.779947+00:00 [queued]>
[2024-09-02T01:17:32.695+0000] {taskinstance.py:1957} INFO - Dependencies all met for dep_context=requeueable deps ti=<TaskInstance: clickhouse_to_sqlite.data_from_clickhouse manual__2024-09-02T01:17:30.779947+00:00 [queued]>
[2024-09-02T01:17:32.695+0000] {taskinstance.py:2171} INFO - Starting attempt 1 of 1
[2024-09-02T01:17:32.703+0000] {taskinstance.py:2192} INFO - Executing <Task(_PythonDecoratedOperator): data_from_clickhouse> on 2024-09-02 01:17:30.779947+00:00
[2024-09-02T01:17:32.709+0000] {standard_task_runner.py:60} INFO - Started process 616 to run task
[2024-09-02T01:17:32.718+0000] {standard_task_runner.py:87} INFO - Running: ['airflow', 'tasks', 'run', 'clickhouse_to_sqlite', 'data_from_clickhouse', 'manual__2024-09-02T01:17:30.779947+00:00', '--job-id', '28', '--raw', '--subdir', 'DAGS_FOLDER/clickhouse_to_sqlite.py', '--cfg-path', '/tmp/tmpsfn94cbl']
[2024-09-02T01:17:32.726+0000] {standard_task_runner.py:88} INFO - Job 28: Subtask data_from_clickhouse
[2024-09-02T01:17:32.785+0000] {task_command.py:423} INFO - Running <TaskInstance: clickhouse_to_sqlite.data_from_clickhouse manual__2024-09-02T01:17:30.779947+00:00 [running]> on host 49db2d0c7729
[2024-09-02T01:17:32.856+0000] {taskinstance.py:2481} INFO - Exporting env vars: AIRFLOW_CTX_DAG_OWNER='airflow' AIRFLOW_CTX_DAG_ID='clickhouse_to_sqlite' AIRFLOW_CTX_TASK_ID='data_from_clickhouse' AIRFLOW_CTX_EXECUTION_DATE='2024-09-02T01:17:30.779947+00:00' AIRFLOW_CTX_TRY_NUMBER='1' AIRFLOW_CTX_DAG_RUN_ID='manual__2024-09-02T01:17:30.779947+00:00'
[2024-09-02T01:17:32.864+0000] {connectionpool.py:824} WARNING - Retrying (Retry(total=0, connect=None, read=None, redirect=0, status=None)) after connection broken by 'NewConnectionError('<urllib3.connection.HTTPSConnection object at 0xffff79b750a0>: Failed to establish a new connection: [Errno 111] Connection refused')': /?wait_end_of_query=1
[2024-09-02T01:17:32.865+0000] {httpclient.py:439} WARNING - Unexpected Http Driver Exception
[2024-09-02T01:17:32.865+0000] {taskinstance.py:2699} ERROR - Task failed with exception
Traceback (most recent call last):
  File "/home/airflow/.local/lib/python3.8/site-packages/urllib3/connection.py", line 174, in _new_conn
    conn = connection.create_connection(
  File "/home/airflow/.local/lib/python3.8/site-packages/urllib3/util/connection.py", line 95, in create_connection
    raise err
  File "/home/airflow/.local/lib/python3.8/site-packages/urllib3/util/connection.py", line 85, in create_connection
    sock.connect(sa)
ConnectionRefusedError: [Errno 111] Connection refused

During handling of the above exception, another exception occurred:

Traceback (most recent call last):
  File "/home/airflow/.local/lib/python3.8/site-packages/urllib3/connectionpool.py", line 715, in urlopen
    httplib_response = self._make_request(
  File "/home/airflow/.local/lib/python3.8/site-packages/urllib3/connectionpool.py", line 404, in _make_request
    self._validate_conn(conn)
  File "/home/airflow/.local/lib/python3.8/site-packages/urllib3/connectionpool.py", line 1058, in _validate_conn
    conn.connect()
  File "/home/airflow/.local/lib/python3.8/site-packages/urllib3/connection.py", line 363, in connect
    self.sock = conn = self._new_conn()
  File "/home/airflow/.local/lib/python3.8/site-packages/urllib3/connection.py", line 186, in _new_conn
    raise NewConnectionError(
urllib3.exceptions.NewConnectionError: <urllib3.connection.HTTPSConnection object at 0xffff79b75040>: Failed to establish a new connection: [Errno 111] Connection refused

During handling of the above exception, another exception occurred:

Traceback (most recent call last):
  File "/home/airflow/.local/lib/python3.8/site-packages/clickhouse_connect/driver/httpclient.py", line 429, in _raw_request
    response = self.http.request(method, url, **kwargs)
  File "/home/airflow/.local/lib/python3.8/site-packages/urllib3/request.py", line 81, in request
    return self.request_encode_body(
  File "/home/airflow/.local/lib/python3.8/site-packages/urllib3/request.py", line 173, in request_encode_body
    return self.urlopen(method, url, **extra_kw)
  File "/home/airflow/.local/lib/python3.8/site-packages/urllib3/poolmanager.py", line 376, in urlopen
    response = conn.urlopen(method, u.request_uri, **kw)
  File "/home/airflow/.local/lib/python3.8/site-packages/urllib3/connectionpool.py", line 827, in urlopen
    return self.urlopen(
  File "/home/airflow/.local/lib/python3.8/site-packages/urllib3/connectionpool.py", line 799, in urlopen
    retries = retries.increment(
  File "/home/airflow/.local/lib/python3.8/site-packages/urllib3/util/retry.py", line 592, in increment
    raise MaxRetryError(_pool, url, error or ResponseError(cause))
urllib3.exceptions.MaxRetryError: HTTPSConnectionPool(host='localhost', port=8443): Max retries exceeded with url: /?wait_end_of_query=1 (Caused by NewConnectionError('<urllib3.connection.HTTPSConnection object at 0xffff79b75040>: Failed to establish a new connection: [Errno 111] Connection refused'))

The above exception was the direct cause of the following exception:

Traceback (most recent call last):
  File "/home/airflow/.local/lib/python3.8/site-packages/airflow/models/taskinstance.py", line 433, in _execute_task
    result = execute_callable(context=context, **execute_callable_kwargs)
  File "/home/airflow/.local/lib/python3.8/site-packages/airflow/decorators/base.py", line 242, in execute
    return_value = super().execute(context)
  File "/home/airflow/.local/lib/python3.8/site-packages/airflow/operators/python.py", line 199, in execute
    return_value = self.execute_callable()
  File "/home/airflow/.local/lib/python3.8/site-packages/airflow/operators/python.py", line 216, in execute_callable
    return self.python_callable(*self.op_args, **self.op_kwargs)
  File "/opt/airflow/dags/clickhouse_to_sqlite.py", line 23, in data_from_clickhouse
    client = clickhouse_connect.get_client(
  File "/home/airflow/.local/lib/python3.8/site-packages/clickhouse_connect/driver/__init__.py", line 115, in create_client
    return HttpClient(interface, host, port, username, password, database, settings=settings, **kwargs)
  File "/home/airflow/.local/lib/python3.8/site-packages/clickhouse_connect/driver/httpclient.py", line 153, in __init__
    super().__init__(database=database,
  File "/home/airflow/.local/lib/python3.8/site-packages/clickhouse_connect/driver/client.py", line 67, in __init__
    tuple(self.command('SELECT version(), timezone()', use_database=False))
  File "/home/airflow/.local/lib/python3.8/site-packages/clickhouse_connect/driver/httpclient.py", line 347, in command
    response = self._raw_request(payload, params, headers, method, fields=fields)
  File "/home/airflow/.local/lib/python3.8/site-packages/clickhouse_connect/driver/httpclient.py", line 441, in _raw_request
    raise OperationalError(f'Error {ex} executing HTTP request attempt {attempts}{err_url}') from ex
clickhouse_connect.driver.exceptions.OperationalError: Error HTTPSConnectionPool(host='localhost', port=8443): Max retries exceeded with url: /?wait_end_of_query=1 (Caused by NewConnectionError('<urllib3.connection.HTTPSConnection object at 0xffff79b75040>: Failed to establish a new connection: [Errno 111] Connection refused')) executing HTTP request attempt 1 (https://localhost:8443)
[2024-09-02T01:17:32.873+0000] {taskinstance.py:1138} INFO - Marking task as FAILED. dag_id=clickhouse_to_sqlite, task_id=data_from_clickhouse, execution_date=20240902T011730, start_date=20240902T011732, end_date=20240902T011732
[2024-09-02T01:17:32.879+0000] {standard_task_runner.py:107} ERROR - Failed to execute job 28 for task data_from_clickhouse (Error HTTPSConnectionPool(host='localhost', port=8443): Max retries exceeded with url: /?wait_end_of_query=1 (Caused by NewConnectionError('<urllib3.connection.HTTPSConnection object at 0xffff79b75040>: Failed to establish a new connection: [Errno 111] Connection refused')) executing HTTP request attempt 1 (https://localhost:8443); 616)
[2024-09-02T01:17:32.904+0000] {local_task_job_runner.py:234} INFO - Task exited with return code 1
[2024-09-02T01:17:32.910+0000] {taskinstance.py:3281} INFO - 0 downstream tasks scheduled from follow-on schedule check
